I'm sorry, but an uncaught exception occurred.

While running game code:
  File "game/scripts/chapters/chapter_0.rpy", line 7, in script
    junetenth """
Exception: Sayer 'junetenth' is not defined.

-- Full Traceback ------------------------------------------------------------

Full traceback:
  File "game/scripts/chapters/chapter_0.rpy", line 7, in script
    junetenth """
  File "C:\Users\cryst\OneDrive\Desktop\L0veRavenRenPy\- RenPy\renpy\ast.py", line 2579, in execute
    Say.execute(self)
  File "C:\Users\cryst\OneDrive\Desktop\L0veRavenRenPy\- RenPy\renpy\ast.py", line 581, in execute
    who = eval_who(self.who, self.who_fast)
  File "C:\Users\cryst\OneDrive\Desktop\L0veRavenRenPy\- RenPy\renpy\ast.py", line 470, in eval_who
    raise Exception("Sayer '%s' is not defined." % who)
Exception: Sayer 'junetenth' is not defined.

Windows-10-10.0.22631 AMD64
Ren'Py 8.3.4.24120703
My Love 1.0
Wed Feb 19 13:10:54 2025
